Workbook
Name startday: '©'!$A$20
Name valuevx: #REF!

Sheet MASTER
A1: ='©'!A17 -> 45108 | K1: (c) 2011 Vertex42 LLC
A2: Neurology Call Schedule
A3: ULH Stroke | C3: ULH General | E3: Jewish | G3: IR | I3: EMU | K3: Jasper/TRH/JS | M3: Good Sam
A4: =UPPER(TEXT(A1,"mmmm yyyy")) -> JULY 2023
A5: =A14 -> 45110 | C5: =C14 -> 45111 | E5: =E14 -> 45112 | G5: =G14 -> 45113 | I5: =I14 -> 45114 | K5: =K14 -> 45115 | M5: =M14 -> 45116
A6: =IF(WEEKDAY($A$1,1)=startday,$A$1,"") | C6: =IF(A6="",IF(WEEKDAY($A$1,1)=MOD(startday,7)+1,$A$1,""),A6+1) | E6: =IF(C6="",IF(WEEKDAY($A$1,1)=MOD(startday,7)+2,$A$1,""),C6+1) | G6: =IF(E6="",IF(WEEKDAY($A$1,1)=MOD(startday,7)+3,$A$1,""),E6+1) | I6: =IF(G6="",IF(WEEKDAY($A$1,1)=MOD(startday,7)+4,$A$1,""),G6+1) | K6: =IF(I6="",IF(WEEKDAY($A$1,1)=MOD(startday,7)+5,$A$1,""),I6+1) -> 45108 | M6: =IF(K6="",IF(WEEKDAY($A$1,1)=MOD(startday+5,7)+1,$A$1,""),K6+1) -> 45109
G7: Ander | I7: Ander | K7: Remmel/Haboubi | M7: Remmel
G8: Holiday | I8: Holiday | K8: Holiday | M8: Holiday
G9: Sagi | I9: Sagi | K9: Sagi/Remmel | M9: Sagi/Remmel
G10: Ding | I10: Ding | K10: Ding | M10: Ding
G11: Shafer | I11: Shafer | K11: Shafer | M11: Shafer
G12: Betsy | I12: Kari (Night All) | K12: Kari (Night All) | M12: Kari (All New)
G13: Haboubi (All) | I13: Haboubi | K13: Haboubi | M13: Haboubi
A14: =M6+1 -> 45110 | C14: =A14+1 -> 45111 | E14: =C14+1 -> 45112 | G14: =E14+1 -> 45113 | I14: =G14+1 -> 45114 | K14: =I14+1 -> 45115 | M14: =K14+1 -> 45116
A22: =M14+1 -> 45117 | C22: =A22+1 -> 45118 | E22: =C22+1 -> 45119 | G22: =E22+1 -> 45120 | I22: =G22+1 -> 45121 | K22: =I22+1 -> 45122 | M22: =K22+1 -> 45123
A30: =M22+1 -> 45124 | C30: =A30+1 -> 45125 | E30: =C30+1 -> 45126 | G30: =E30+1 -> 45127 | I30: =G30+1 -> 45128 | K30: =I30+1 -> 45129 | M30: =K30+1 -> 45130
A38: =IF(M30="","",IF(MONTH(M30+1)<>MONTH($A$1),"",M30+1)) -> 45131 | C38: =IF(A38="","",IF(MONTH(A38+1)<>MONTH($A$1),"",A38+1)) -> 45132 | E38: =IF(C38="","",IF(MONTH(C38+1)<>MONTH($A$1),"",C38+1)) -> 45133 | G38: =IF(E38="","",IF(MONTH(E38+1)<>MONTH($A$1),"",E38+1)) -> 45134 | I38: =IF(G38="","",IF(MONTH(G38+1)<>MONTH($A$1),"",G38+1)) -> 45135 | K38: =IF(I38="","",IF(MONTH(I38+1)<>MONTH($A$1),"",I38+1)) -> 45136 | M38: =IF(K38="","",IF(MONTH(K38+1)<>MONTH($A$1),"",K38+1)) -> 45137
A46: =IF(M38="","",IF(MONTH(M38+1)<>MONTH($A$1),"",M38+1)) -> 45138 | C46: =IF(A46="","",IF(MONTH(A46+1)<>MONTH($A$1),"",A46+1)) | E46: Notes:
E53: © 2011-2019 by Vertex42.com. Free to print. | I53: =HYPERLINK("https://www.vertex42.com/calendars/academic-calendar.html","https://www.vertex42.com/calendars/academic-calendar.html") -> https://www.vertex42.com/calendars/academic-calendar.html

Sheet Mar2021
A1: =EDATE('©'!A17,8) -> 45352 | K1: (c) 2011 Vertex42 LLC
A2: Neurology Call Schedule
A3: ULH Stroke | C3: ULH General | E3: Jewish | G3: IR | I3: EMU | K3: Jasper/TRH/JS | M3: Good Sam
A4: =UPPER(TEXT(A1,"mmmm yyyy")) -> MARCH 2024
A5: =A14 -> 45355 | C5: =C14 -> 45356 | E5: =E14 -> 45357 | G5: =G14 -> 45358 | I5: =I14 -> 45359 | K5: =K14 -> 45360 | M5: =M14 -> 45361
A6: =IF(WEEKDAY($A$1,1)=startday,$A$1,"") | C6: =IF(A6="",IF(WEEKDAY($A$1,1)=MOD(startday,7)+1,$A$1,""),A6+1) | E6: =IF(C6="",IF(WEEKDAY($A$1,1)=MOD(startday,7)+2,$A$1,""),C6+1) | G6: =IF(E6="",IF(WEEKDAY($A$1,1)=MOD(startday,7)+3,$A$1,""),E6+1) | I6: =IF(G6="",IF(WEEKDAY($A$1,1)=MOD(startday,7)+4,$A$1,""),G6+1) -> 45352 | K6: =IF(I6="",IF(WEEKDAY($A$1,1)=MOD(startday,7)+5,$A$1,""),I6+1) -> 45353 | M6: =IF(K6="",IF(WEEKDAY($A$1,1)=MOD(startday+5,7)+1,$A$1,""),K6+1) -> 45354
A7: Liu | C7: Liu | E7: Liu | G7: Liu | I7: Liu | K7: Liu | M7: Liu
A8: Holiday | C8: Holiday | E8: Holiday | G8: Holiday | I8: Shafer | K8: Shafer | M8: Shafer
A9: Sagi | C9: Sagi | E9: Sagi | G9: Sagi | I9: Sagi | K9: Sagi | M9: Sagi
A10: Liu | C10: Liu | E10: Liu | G10: Liu | I10: Liu | K10: Liu | M10: Liu
A11: Palade | C11: Palade | E11: Palade | G11: Palade | I11: Palade | K11: Palade | M11: Palade
A12: Kari | C12: Kari (Night) | E12: Betsy (Night) | G12: Kari (Night) | I12: Kari (Night) | K12: Kari (All New) | M12: Kari (All New)
A13: Pham (Night) | C13: Pham | E13: Pham | G13: Pham | I13: Pham | K13: Pham | M13: Pham
A14: =M6+1 -> 45355 | C14: =A14+1 -> 45356 | E14: =C14+1 -> 45357 | G14: =E14+1 -> 45358 | I14: =G14+1 -> 45359 | K14: =I14+1 -> 45360 | M14: =K14+1 -> 45361
A15: Liu | C15: Liu | E15: Liu | G15: Liu | I15: Ander/Remmel | K15: Ander | M15: Ander
A16: Shafer | C16: Shafer | E16: Shafer | G16: Palade | I16: Palade | K16: Palade | M16: Palade
A17: Remmel | C17: Ander/Remmel | E17: Ander/Remmel | G17: Ander/Remmel | I17: Remmel | K17: Nord/Ander | M17: Nord/Ander
A18: Ding | C18: Ding | E18: Ding | G18: Ding | I18: Ding | K18: Ding | M18: Ding
A19: Sagi | C19: Sagi | E19: Sagi | G19: Sagi | I19: Sagi | K19: Sagi | M19: Sagi
A20: Kari (Night) | C20: Kari (Night) | E20: Betsy (Night) | G20: Betsy/Kari (Night) | I20: Betsy | K20: Betsy | M20: Betsy
A21: Nancy | C21: Nancy | E21: Nancy | G21: Nancy | I21: Nancy/Marwa (Night) | K21: Betsy (All New) | M21: Marwa (All New)
A22: =M14+1 -> 45362 | C22: =A22+1 -> 45363 | E22: =C22+1 -> 45364 | G22: =E22+1 -> 45365 | I22: =G22+1 -> 45366 | K22: =I22+1 -> 45367 | M22: =K22+1 -> 45368
A23: Ander/Remmel | C23: Ander | E23: Ander | G23: Ander | I23: Liu | K23: Liu | M23: Liu
A24: Palade | C24: Palade | E24: Palade | G24: Palade | I24: Feng | K24: Feng | M24: Feng
A25: Remmel | C25: Remmel | E25: Remmel/Ander | G25: Hernandez | I25: Hernandez | K25: Hernandez | M25: Hernandez
A26: Ding | C26: Liu | E26: Liu | G26: Ding | I26: Liu | K26: Liu | M26: Liu
A27: Sagi | C27: Sagi | E27: Sagi | G27: Sagi | I27: Sagi | K27: Sagi | M27: Sagi
A28: Betsy (Night) | C28: Betsy | E28: Betsy (Night) | G28: Kari | I28: Kari | K28: Kari | M28: Kari
A29: Pham | C29: Pham (Night) | E29: Pham | G29: Pham (Night) | I29: Pham (Night) | K29: Pham (All New) | M29: Pham (All New)
A30: =M22+1 -> 45369 | C30: =A30+1 -> 45370 | E30: =C30+1 -> 45371 | G30: =E30+1 -> 45372 | I30: =G30+1 -> 45373 | K30: =I30+1 -> 45374 | M30: =K30+1 -> 45375
A31: Liu | C31: Liu | E31: Liu | G31: Liu | I31: Remmel/Ander | K31: Remmel | M31: Remmel
A32: Feng | C32: Feng | E32: Feng | G32: Feng | I32: Robertson | K32: Robertson | M32: Robertson
A33: Remmel | C33: Ander | E33: Ander/Remmel | G33: Ander | I33: Ander | K33: Ander/Remmel | M33: Ander/Remmel
A34: Liu | C34: Liu | E34: Liu | G34: Liu | I34: Ding | K34: Ding | M34: Ding
A35: Evans | C35: Evans | E35: Evans | G35: Evans | I35: Evans | K35: Evans | M35: Evans
A36: Kari/Betsy (Night) | C36: Kari (Night) | E36: Betsy (Night) | G36: Betsy/Kari (Night) | I36: Betsy | K36: Betsy | M36: Betsy
A37: Nancy | C37: Nancy | E37: Nancy | G37: Nancy | I37: Nancy/Marwa (Night) | K37: Marwa (All New) | M37: Marwa (All New)
A38: =IF(M30="","",IF(MONTH(M30+1)<>MONTH($A$1),"",M30+1)) -> 45376 | C38: =IF(A38="","",IF(MONTH(A38+1)<>MONTH($A$1),"",A38+1)) -> 45377 | E38: =IF(C38="","",IF(MONTH(C38+1)<>MONTH($A$1),"",C38+1)) -> 45378 | G38: =IF(E38="","",IF(MONTH(E38+1)<>MONTH($A$1),"",E38+1)) -> 45379 | I38: =IF(G38="","",IF(MONTH(G38+1)<>MONTH($A$1),"",G38+1)) -> 45380 | K38: =IF(I38="","",IF(MONTH(I38+1)<>MONTH($A$1),"",I38+1)) -> 45381 | M38: =IF(K38="","",IF(MONTH(K38+1)<>MONTH($A$1),"",K38+1)) -> 45382
A39: Remmel/Ander | C39: Remmel | E39: Remmel/Ander
A40: Robertson | C40: Robertson | E40: Robertson
...

Sheet Apr2021
A1: =EDATE('©'!A17,9) -> 45383 | K1: (c) 2011 Vertex42 LLC
A2: Neurology Call Schedule
A3: ULH Stroke | C3: ULH General | E3: Jewish | G3: IR | I3: EMU | K3: Jasper/TRH/JS | M3: Good Sam
A4: =UPPER(TEXT(A1,"mmmm yyyy")) -> APRIL 2024
A5: =A14 -> 45390 | C5: =C14 -> 45391 | E5: =E14 -> 45392 | G5: =G14 -> 45393 | I5: =I14 -> 45394 | K5: =K14 -> 45395 | M5: =M14 -> 45396
A6: =IF(WEEKDAY($A$1,1)=startday,$A$1,"") -> 45383 | C6: =IF(A6="",IF(WEEKDAY($A$1,1)=MOD(startday,7)+1,$A$1,""),A6+1) -> 45384 | E6: =IF(C6="",IF(WEEKDAY($A$1,1)=MOD(startday,7)+2,$A$1,""),C6+1) -> 45385 | G6: =IF(E6="",IF(WEEKDAY($A$1,1)=MOD(startday,7)+3,$A$1,""),E6+1) -> 45386 | I6: =IF(G6="",IF(WEEKDAY($A$1,1)=MOD(startday,7)+4,$A$1,""),G6+1) -> 45387 | K6: =IF(I6="",IF(WEEKDAY($A$1,1)=MOD(startday,7)+5,$A$1,""),I6+1) -> 45388 | M6: =IF(K6="",IF(WEEKDAY($A$1,1)=MOD(startday+5,7)+1,$A$1,""),K6+1) -> 45389
G7: Remmel | I7: Haboubi/Remmel | K7: Haboubi | M7: Haboubi
G8: Robertson | I8: Wang | K8: Wang | M8: Wang
G9: Ander | I9: Sagi/Remmel | K9: Sagi | M9: Sagi
G10: Ding | I10: Ding | K10: Ding | M10: Ding
G11: Palade | I11: Palade | K11: Palade | M11: Palade
G12: Kari (Night) | I12: Kari | K12: Kari | M12: Kari
G13: Pham | I13: Pham (Night) | K13: Pham (All New) | M13: Pham (All New)
A14: =M6+1 -> 45390 | C14: =A14+1 -> 45391 | E14: =C14+1 -> 45392 | G14: =E14+1 -> 45393 | I14: =G14+1 -> 45394 | K14: =I14+1 -> 45395 | M14: =K14+1 -> 45396
A15: Haboubi | C15: Haboubi | E15: Haboubi/Ander | G15: Haboubi | I15: Ander/Remmel | K15: Ander/Haboubi | M15: Ander
A16: Wang | C16: Wang | E16: Wang | G16: Wang | I16: Hedera | K16: Hedera | M16: Hedera
A17: Sagi | C17: Sagi | E17: Sagi/Ander | G17: Sagi | I17: Sagi/Remmel | K17: Hernandez | M17: Hernandez
A18: Liu | C18: Liu | E18: Liu | G18: Liu | I18: Liu | K18: Liu | M18: Liu
A19: Shafer | C19: Shafer | E19: Shafer | G19: Shafer | I19: Shafer | K19: Shafer | M19: Shafer
A20: Kari (Night) | C20: Kari (Night) | E20: Kari (Night) | G20: Kari (Night) | I20: Kari | K20: Kari | M20: Kari
A21: Pham | C21: Pham | E21: Pham | G21: Pham | I21: Pham/Elnazeir Night | K21: Elnazeir (AllNew) | M21: Elnazeir (All New)
A22: =M14+1 -> 45397 | C22: =A22+1 -> 45398 | E22: =C22+1 -> 45399 | G22: =E22+1 -> 45400 | I22: =G22+1 -> 45401 | K22: =I22+1 -> 45402 | M22: =K22+1 -> 45403
A23: Ander/Ander | C23: Ander | E23: Ander | G23: Ander | I23: Liu | K23: Liu | M23: Liu
A24: Hedera | C24: Hedera | E24: Hedera | G24: Hedera | I24: Brown | K24: Brown | M24: Brown
A25: Remmel/Ander | C25: Remmel | E25: Remmel/Ander | G25: Hernandez | I25: Hernandez | K25: Nord | M25: Nord
A26: Ding | C26: Ding | E26: Ding | G26: Ding | I26: Ding | K26: Ding | M26: Ding
A27: Sagi | C27: Sagi | E27: Sagi | G27: Sagi | I27: Sagi | K27: Sagi | M27: Sagi
A28: Kari (Night) | C28: Kari (Night) | E28: Betsy (Night) | G28: Betsy | I28: Betsy (Night) | K28: Betsy (All New) | M28: Betsy (All New)
A29: Haboubi | C29: Haboubi | E29: Haboubi | G29: Haboubi (night) | I29: Haboubi | K29: Haboubi | M29: Haboubi
A30: =M22+1 -> 45404 | C30: =A30+1 -> 45405 | E30: =C30+1 -> 45406 | G30: =E30+1 -> 45407 | I30: =G30+1 -> 45408 | K30: =I30+1 -> 45409 | M30: =K30+1 -> 45410
A31: Liu | C31: Liu | E31: Liu | G31: Liu | I31: Liu | K31: Remmel | M31: Remmel
A32: Brown | C32: Brown | E32: Brown | G32: Brown | I32: Holiday | K32: Holiday | M32: Holiday
A33: Ander | C33: Ander | E33: Ander | G33: Ander | I33: Ander | K33: Nord/Remmel | M33: Nord/Remmel
A34: Liu | C34: Liu | E34: Liu | G34: Liu | I34: Liu | K34: Liu | M34: Liu
A35: Shafer | C35: Shafer | E35: Shafer | G35: Shafer | I35: Shafer | K35: Shafer | M35: Shafer
A36: Betsy | C36: Betsy | E36: Betsy | G36: Kari (Night) | I36: Kari | K36: Kari | M36: Kari
A37: Haboubi (Night) | C37: Haboubi (Night) | E37: Haboubi (Night) | G37: Haboubi | I37: Haboubi/Elnazeir Night | K37: Elnazeir (All New) | M37: Elnazeir (All New)
A38: =IF(M30="","",IF(MONTH(M30+1)<>MONTH($A$1),"",M30+1)) -> 45411 | C38: =IF(A38="","",IF(MONTH(A38+1)<>MONTH($A$1),"",A38+1)) -> 45412 | E38: =IF(C38="","",IF(MONTH(C38+1)<>MONTH($A$1),"",C38+1)) | G38: =IF(E38="","",IF(MONTH(E38+1)<>MONTH($A$1),"",E38+1)) | I38: =IF(G38="","",IF(MONTH(G38+1)<>MONTH($A$1),"",G38+1)) | K38: =IF(I38="","",IF(MONTH(I38+1)<>MONTH($A$1),"",I38+1)) | M38: =IF(K38="","",IF(MONTH(K38+1)<>MONTH($A$1),"",K38+1))
A39: Remmel/Haboubi | C39: Remmel | E39: Liu | G39: Liu | I39: Liu
A40: Holiday | C40: Holiday | E40: Holiday | G40: Holiday | I40: Feng
...

Sheet May2021
A1: =EDATE('©'!A17,10) -> 45413
A2: Neurology Call Schedule
A3: ULH Stroke | C3: ULH General | E3: Jewish | G3: IR | I3: EMU | K3: Jasper/TRH/JS | M3: Good Sam
A4: =UPPER(TEXT(A1,"mmmm yyyy")) -> MAY 2024
A5: =A14 -> 45418 | C5: =C14 -> 45419 | E5: =E14 -> 45420 | G5: =G14 -> 45421 | I5: =I14 -> 45422 | K5: =K14 -> 45423 | M5: =M14 -> 45424
A6: =IF(WEEKDAY($A$1,1)=startday,$A$1,"") | C6: =IF(A6="",IF(WEEKDAY($A$1,1)=MOD(startday,7)+1,$A$1,""),A6+1) | E6: =IF(C6="",IF(WEEKDAY($A$1,1)=MOD(startday,7)+2,$A$1,""),C6+1) -> 45413 | G6: =IF(E6="",IF(WEEKDAY($A$1,1)=MOD(startday,7)+3,$A$1,""),E6+1) -> 45414 | I6: =IF(G6="",IF(WEEKDAY($A$1,1)=MOD(startday,7)+4,$A$1,""),G6+1) -> 45415 | K6: =IF(I6="",IF(WEEKDAY($A$1,1)=MOD(startday,7)+5,$A$1,""),I6+1) -> 45416 | M6: =IF(K6="",IF(WEEKDAY($A$1,1)=MOD(startday+5,7)+1,$A$1,""),K6+1) -> 45417
K7: Liu | M7: Liu
K8: Feng | M8: Feng
K9: Hernandez | M9: Hernandez
K10: Liu | M10: Liu
K11: Palade | M11: Palade
K12: Betsy (All New) | M12: Betsy (All New
K13: Pham | M13: Pham
A14: =M6+1 -> 45418 | C14: =A14+1 -> 45419 | E14: =C14+1 -> 45420 | G14: =E14+1 -> 45421 | I14: =G14+1 -> 45422 | K14: =I14+1 -> 45423 | M14: =K14+1 -> 45424
A15: Liu | C15: Liu | E15: Liu | G15: Liu | I15: Ander/Remmel | K15: Ander | M15: Ander
A16: Feng | C16: Feng | E16: Feng | G16: Feng | I16: Shafer | K16: Shafer | M16: Shafer
A17: Sagi | C17: Sagi | E17: Sagi | G17: Sagi | I17: Sagi | K17: Sagi/Ander | M17: Sagi/Ander
A18: Liu | C18: Liu | E18: Liu | G18: Ding | I18: Ding | K18: Ding | M18: Ding
A19: Palade | C19: Palade | E19: Palade | G19: Palade | I19: Palade | K19: Palade | M19: Palade
A20: Kari (Night) | C20: Kari (Night) | E20: Betsy (Night) | G20: Kari (Night) | I20: Kari | K20: Kari | M20: Kari
A21: Haboubi | C21: Haboubi | E21: Haboubi | G21: Haboubi | I21: Haboubi/Elnazier (Night) | K21: Elnazier (All New) | M21: Elnazier (All New)
A22: =M14+1 -> 45425 | C22: =A22+1 -> 45426 | E22: =C22+1 -> 45427 | G22: =E22+1 -> 45428 | I22: =G22+1 -> 45429 | K22: =I22+1 -> 45430 | M22: =K22+1 -> 45431
A23: Ander/Haboubi | C23: Ander | E23: Ander/Ander | G23: Ander | I23: Remmel/Ander | K23: Remmel | M23: Remmel
A24: Shafer | C24: Shafer | E24: Shafer | G24: Shafer | I24: Brown | K24: Brown | M24: Brown
A25: Remmel | C25: Remmel | E25: Remmel | G25: Remmel | I25: Ander | K25: Nord/Remmel | M25: Nord/Remmel
A26: Liu | C26: Liu | E26: Liu | G26: Liu | I26: Liu | K26: Liu | M26: Liu
A27: Sagi | C27: Sagi | E27: Sagi | G27: Sagi | I27: Sagi | K27: Sagi | M27: Sagi
A28: Kari (Night) | C28: Kari (Night) | E28: Betsy (Night) | G28: Betsy | I28: Betsy | K28: Betsy | M28: Betsy
A29: Haboubi | C29: Haboubi | E29: Haboubi | G29: Haboubi (Night) | I29: Haboubi (Night) | K29: Haboubi (All New) | M29: Haboubi (All New)
A30: =M22+1 -> 45432 | C30: =A30+1 -> 45433 | E30: =C30+1 -> 45434 | G30: =E30+1 -> 45435 | I30: =G30+1 -> 45436 | K30: =I30+1 -> 45437 | M30: =K30+1 -> 45438
A31: Remmel/Ander | C31: Remmel | E31: Remmel/Remmel | G31: Remmel | I31: Haboubi/Remmel | K31: Haboubi | M31: Haboubi
A32: Brown | C32: Brown | E32: Brown | G32: Brown | I32: Wang | K32: Wang | M32: Wang
A33: Ander | C33: Ander | E33: Ander/Remmel | G33: Ander | I33: Ander/Remmel | K33: Elnazeir | M33: Elnazeir
A34: Ding | C34: Ding | E34: Ding | G34: Ding | I34: Ding | K34: Ding | M34: Ding
A35: Shafer | C35: Shafer | E35: Shafer | G35: Shafer | I35: Shafer | K35: Shafer | M35: Shafer
A36: Kari (Night) | C36: Kari (Night) | E36: Kari | G36: Kari | I36: Kari (Night) | K36: Kari (All New) | M36: Kari (All New)
A37: Pham | C37: Pham | E37: Pham (Night) | G37: Pham (Night) | I37: Pham | K37: Pham | M37: Pham
A38: =IF(M30="","",IF(MONTH(M30+1)<>MONTH($A$1),"",M30+1)) -> 45439 | C38: =IF(A38="","",IF(MONTH(A38+1)<>MONTH($A$1),"",A38+1)) -> 45440 | E38: =IF(C38="","",IF(MONTH(C38+1)<>MONTH($A$1),"",C38+1)) -> 45441 | G38: =IF(E38="","",IF(MONTH(E38+1)<>MONTH($A$1),"",E38+1)) -> 45442 | I38: =IF(G38="","",IF(MONTH(G38+1)<>MONTH($A$1),"",G38+1)) -> 45443 | K38: =IF(I38="","",IF(MONTH(I38+1)<>MONTH($A$1),"",I38+1)) | M38: =IF(K38="","",IF(MONTH(K38+1)<>MONTH($A$1),"",K38+1))
A39: Haboubi/Ander | C39: Haboubi | E39: Haboubi/Haboubi | G39: Haboubi | I39: Ander/Remmel | K39: Ander | M39: Ander
A40: Wang | C40: Wang | E40: Wang | G40: Wang | I40: Palade | K40: Palade | M40: Palade
...

Sheet Jun2021
A1: =EDATE('©'!A17,11) -> 45444
A2: Neurology Call Schedule
A3: ULH Stroke | C3: ULH General | E3: Jewish | G3: IR | I3: EMU | K3: Jasper/TRH/JS | M3: Good Sam
A4: =UPPER(TEXT(A1,"mmmm yyyy")) -> JUNE 2024
A5: =A14 -> 45446 | C5: =C14 -> 45447 | E5: =E14 -> 45448 | G5: =G14 -> 45449 | I5: =I14 -> 45450 | K5: =K14 -> 45451 | M5: =M14 -> 45452
A6: =IF(WEEKDAY($A$1,1)=startday,$A$1,"") | C6: =IF(A6="",IF(WEEKDAY($A$1,1)=MOD(startday,7)+1,$A$1,""),A6+1) | E6: =IF(C6="",IF(WEEKDAY($A$1,1)=MOD(startday,7)+2,$A$1,""),C6+1) | G6: =IF(E6="",IF(WEEKDAY($A$1,1)=MOD(startday,7)+3,$A$1,""),E6+1) | I6: =IF(G6="",IF(WEEKDAY($A$1,1)=MOD(startday,7)+4,$A$1,""),G6+1) | K6: =IF(I6="",IF(WEEKDAY($A$1,1)=MOD(startday,7)+5,$A$1,""),I6+1) -> 45444 | M6: =IF(K6="",IF(WEEKDAY($A$1,1)=MOD(startday+5,7)+1,$A$1,""),K6+1) -> 45445
C7: Ander | E7: Ander/Ander | G7: Ander | I7: Haboubi/Haboubi | K7: Haboubi | M7: Haboubi/Ander
C8: Palade | E8: Palade | G8: Palade | I8: Holiday | K8: Holiday | M8: Holiday
C9: Remmel | E9: Remmel/Ander | G9: Remmel | I9: Ander/Haboubi | K9: Remmel/Haboubi | M9: Remmel/Ander
C10: Ding | E10: Ding | G10: Ding | I10: Ding | K10: Ding | M10: Ding
C11: Palade | E11: Palade | G11: Palade | I11: Palade | K11: Palade | M11: Palade
C12: Kari | E12: Betsy (Night) | G12: Kari (Night) | I12: Kari | K12: Betsy | M12: Betsy
C13: Haboubi (Night) | E13: Haboubi | G13: Haboubi | I13: Pham/Elnazeir (Night) | K13: Elnazeir (All New) | M13: Elnazeir (All New)
A14: =M6+1 -> 45446 | C14: =A14+1 -> 45447 | E14: =C14+1 -> 45448 | G14: =E14+1 -> 45449 | I14: =G14+1 -> 45450 | K14: =I14+1 -> 45451 | M14: =K14+1 -> 45452
A15: Haboubi/Ander | C15: Haboubi | E15: Haboubi/Haboubi | G15: Haboubi | I15: Remmel/Haboubi | K15: Remmel | M15: Remmel
A16: Holiday | C16: Holiday | E16: Holiday | G16: Holiday | I16: Feng | K16: Feng | M16: Feng
A17: Ander/Ander | C17: Ander | E17: Ander/Haboubi | G17: Ander | I17: Ander/Haboubi | K17: Hernandez/Remmel | M17: Hernandez/Remmel
A18: Liu | C18: Liu | E18: Ding | G18: Ding | I18: Ding | K18: Ding | M18: Ding
A19: Evans | C19: Evans | E19: Evans | G19: Evans | I19: Evans | K19: Evans | M19: Evans
A20: Betsy | C20: Betsy | E20: Betsy (Night) | G20: Kari | I20: Kari (Night) | K20: Kari (All New) | M20: Kari (All New)
A21: Pham (Night) | C21: Pham (Night) | E21: Pham | G21: Pham (Night) | I21: Pham | K21: Pham | M21: Pham
A22: =M14+1 -> 45453 | C22: =A22+1 -> 45454 | E22: =C22+1 -> 45455 | G22: =E22+1 -> 45456 | I22: =G22+1 -> 45457 | K22: =I22+1 -> 45458 | M22: =K22+1 -> 45459
A23: Liu | C23: Liu | E23: Liu | G23: Liu | I23: Liu | K23: Liu | M23: Liu
A24: Feng | C24: Feng | E24: Feng | G24: Feng | I24: Hedera | K24: Hedera | M24: Hedera
A25: Remmel | C25: Remmel | E25: Remmel | G25: Remmel | I25: Remmel/Liu | K25: Elnazeir | M25: Elnazeir
A26: Liu | C26: Liu | E26: Liu | G26: Liu | I26: Liu | K26: Liu | M26: Liu
A27: Shafer | C27: Shafer | E27: Shafer | G27: Shafer | I27: Shafer | K27: Shafer | M27: Shafer
A28: Betsy | C28: Betsy | E28: Betsy (Night) | G28: Betsy | I28: Betsy (Night) | K28: Betsy (All New) | M28: Betsy (All New)
A29: Haboubi (Night) | C29: Haboubi (Night) | E29: Haboubi | G29: Haboubi (Night) | I29: Haboubi | K29: Haboubi | M29: Haboubi
A30: =M22+1 -> 45460 | C30: =A30+1 -> 45461 | E30: =C30+1 -> 45462 | G30: =E30+1 -> 45463 | I30: =G30+1 -> 45464 | K30: =I30+1 -> 45465 | M30: =K30+1 -> 45466
A31: Liu/Ander | C31: Liu | E31: Liu | G31: Liu | I31: Ander/Remmel | K31: Ander | M31: Ander
A32: Hedera | C32: Hedera | E32: Hedera | G32: Hedera | I32: Robertson | K32: Robertson | M32: Robertson
A33: Ander | C33: Ander | E33: Ander | G33: Ander | I33: Remmel/Remmel | K33: Remmel/Ander | M33: Remmel/Ander
A34: Ding | C34: Liu | E34: Liu | G34: Liu | I34: Liu | K34: Liu | M34: Liu
A35: Shafer | C35: Shafer | E35: Shafer | G35: Shafer | I35: Shafer | K35: Shafer | M35: Shafer
A36: Kari (Night) | C36: Kari (Night) | E36: Kari (Night) | G36: Kari (Night) | I36: Kari | K36: Kari | M36: Kari (All New)
A37: Haboubi | C37: Haboubi | E37: Haboubi | G37: Haboubi | I37: Haboubi (Night) | K37: Haboubi (All New) | M37: Haboubi
A38: =IF(M30="","",IF(MONTH(M30+1)<>MONTH($A$1),"",M30+1)) -> 45467 | C38: =IF(A38="","",IF(MONTH(A38+1)<>MONTH($A$1),"",A38+1)) -> 45468 | E38: =IF(C38="","",IF(MONTH(C38+1)<>MONTH($A$1),"",C38+1)) -> 45469 | G38: =IF(E38="","",IF(MONTH(E38+1)<>MONTH($A$1),"",E38+1)) -> 45470 | I38: =IF(G38="","",IF(MONTH(G38+1)<>MONTH($A$1),"",G38+1)) -> 45471 | K38: =IF(I38="","",IF(MONTH(I38+1)<>MONTH($A$1),"",I38+1)) -> 45472 | M38: =IF(K38="","",IF(MONTH(K38+1)<>MONTH($A$1),"",K38+1)) -> 45473
A39: Ander/Haboubi | C39: Ander | E39: Ander/Ander
A40: Robertson | C40: Robertson | E40: Robertson
...

Sheet Jul2021
A1: =EDATE('©'!A17,12) -> 45474
A2: Neurology Call Schedule
A3: ULH Stroke | C3: ULH General | E3: Jewish | G3: IR | I3: EMU | K3: Jasper/TRH/JS | M3: Good Sam
A4: =UPPER(TEXT(A1,"mmmm yyyy")) -> JULY 2024
A5: =A14 -> 45481 | C5: =C14 -> 45482 | E5: =E14 -> 45483 | G5: =G14 -> 45484 | I5: =I14 -> 45485 | K5: =K14 -> 45486 | M5: =M14 -> 45487
A6: =IF(WEEKDAY($A$1,1)=startday,$A$1,"") -> 45474 | C6: =IF(A6="",IF(WEEKDAY($A$1,1)=MOD(startday,7)+1,$A$1,""),A6+1) -> 45475 | E6: =IF(C6="",IF(WEEKDAY($A$1,1)=MOD(startday,7)+2,$A$1,""),C6+1) -> 45476 | G6: =IF(E6="",IF(WEEKDAY($A$1,1)=MOD(startday,7)+3,$A$1,""),E6+1) -> 45477 | I6: =IF(G6="",IF(WEEKDAY($A$1,1)=MOD(startday,7)+4,$A$1,""),G6+1) -> 45478 | K6: =IF(I6="",IF(WEEKDAY($A$1,1)=MOD(startday,7)+5,$A$1,""),I6+1) -> 45479 | M6: =IF(K6="",IF(WEEKDAY($A$1,1)=MOD(startday+5,7)+1,$A$1,""),K6+1) -> 45480
G7: Ander | I7: Haboubi | K7: Haboubi | M7: Haboubi
G8: Robertson | I8: Shafer | K8: Shafer | M8: Shafer
G9: Remmel/Ander | I9: Sagi | K9: Hernandez/Haboubi | M9: Hernandez/Haboubi
G10: Ding | I10: Ding | K10: Ding | M10: Ding
G11: Palade | I11: Palade | K11: Palade | M11: Palade
G12: Betsy | I12: Betsy (Night) | K12: Betsy (All New) | M12: Betsy (All New)
G13: Pham (Night) | I13: Pham | K13: Pham | M13: Pham
A14: =M6+1 -> 45481 | C14: =A14+1 -> 45482 | E14: =C14+1 -> 45483 | G14: =E14+1 -> 45484 | I14: =G14+1 -> 45485 | K14: =I14+1 -> 45486 | M14: =K14+1 -> 45487
A15: Haboubi/Remmel | C15: Haboubi | E15: Haboubi | G15: Haboubi | I15: Remmel/Ander | K15: Remmel | M15: Remmel
A16: Shafer | C16: Shafer | E16: Shafer | G16: Shafer | I16: Palade | K16: Palade | M16: Palade
A17: Sagi | C17: Sagi | E17: Sagi | G17: Sagi | I17: Ander | K17: Ander/Remmel | M17: Ander/Remmel
A18: Ding | C18: Ding | E18: Ding | G18: Ding | I18: Abecassis | K18: Abecassis | M18: Abecassis
A19: Palade | C19: Palade | E19: Palade | G19: Palade | I19: Sagi | K19: Sagi | M19: Sagi
A20: Kari | C20: Kari | E20: Betsy (Night) | G20: Kari (Night) | I20: Kari | K20: Kari | M20: Kari
A21: Pham (Night) | C21: Pham (Night) | E21: Pham | G21: Pham | I21: Pham (Night) | K21: Pham (All new) | M21: Pham (All New)
A22: =M14+1 -> 45488 | C22: =A22+1 -> 45489 | E22: =C22+1 -> 45490 | G22: =E22+1 -> 45491 | I22: =G22+1 -> 45492 | K22: =I22+1 -> 45493 | M22: =K22+1 -> 45494
A23: Remmel/Ander | C23: Remmel | E23: Remmel | G23: Remmel | I23: Liu | K23: Liu | M23: Liu
A24: Palade | C24: Palade | E24: Palade | G24: Palade | I24: Wang | K24: Wang | M24: Wang
A25: Ander | C25: Ander | E25: Ander | G25: Ander/Remmel-3pm | I25: Remmel/Liu | K25: Remmel/Liu | M25: Remmel/Liu
A26: Abecassis | C26: Abecassis | E26: Liu | G26: Liu | I26: Liu | K26: Liu | M26: Liu
A27: Sagi | C27: Sagi | E27: Sagi | G27: Sagi | I27: Sagi | K27: Sagi | M27: Sagi
A28: Kari (Night) | C28: Kari (Night) | E28: Betsy (Night) | G28: Betsy | I28: Betsy | K28: Betsy | M28: Betsy
A29: Pham | C29: Pham | E29: Pham | G29: Haboubi (Night) | I29: Haboubi (Night) | K29: Haboubi (All New) | M29: Haboubi (All New)
A30: =M22+1 -> 45495 | C30: =A30+1 -> 45496 | E30: =C30+1 -> 45497 | G30: =E30+1 -> 45498 | I30: =G30+1 -> 45499 | K30: =I30+1 -> 45500 | M30: =K30+1 -> 45501
A31: Liu | C31: Liu | E31: Liu | G31: Liu | I31: Ander/Haboubi | K31: Ander | M31: Ander
A32: Wang | C32: Wang | E32: Wang | G32: Wang | I32: Brown | K32: Brown | M32: Brown
A33: Remmel | C33: Remmel | E33: Remmel | G33: Remmel | I33: Sagi | K33: Sagi/Ander | M33: Sagi/Ander
A34: Liu | C34: Liu | E34: Liu | G34: Ding | I34: Ding | K34: Ding | M34: Ding
A35: Evans | C35: Evans | E35: Evans | G35: Evans | I35: Evans | K35: Evans | M35: Evans
A36: Betsy (Night) | C36: Betsy | E36: Betsy (Night) | G36: Kari | I36: Kari (Night) | K36: Kari (All New) | M36: Kari (All New)
A37: Haboubi | C37: Haboubi (Night) | E37: Haboubi | G37: Haboubi (Night) | I37: Haboubi | K37: Haboubi | M37: Haboubi
A38: =IF(M30="","",IF(MONTH(M30+1)<>MONTH($A$1),"",M30+1)) -> 45502 | C38: =IF(A38="","",IF(MONTH(A38+1)<>MONTH($A$1),"",A38+1)) -> 45503 | E38: =IF(C38="","",IF(MONTH(C38+1)<>MONTH($A$1),"",C38+1)) -> 45504 | G38: =IF(E38="","",IF(MONTH(E38+1)<>MONTH($A$1),"",E38+1)) | I38: =IF(G38="","",IF(MONTH(G38+1)<>MONTH($A$1),"",G38+1)) | K38: =IF(I38="","",IF(MONTH(I38+1)<>MONTH($A$1),"",I38+1)) | M38: =IF(K38="","",IF(MONTH(K38+1)<>MONTH($A$1),"",K38+1))
A39: Ander/Haboubi | C39: Ander | E39: Ander/Liu | G39: Ander | I39: Haboubi/Liu | K39: Haboubi
A40: Brown | C40: Brown | E40: Brown | G40: Brown | I40: Holiday | K40: Holiday
...

Sheet Aug2021
A1: =EDATE('©'!A17,13) -> 45505
A2: Neurology Call Schedule
A3: ULH Stroke | C3: ULH General | E3: Jewish | G3: IR | I3: EMU | K3: Jasper/TRH/JS | M3: Good Sam
A4: =UPPER(TEXT(A1,"mmmm yyyy")) -> AUGUST 2024
A5: =A14 -> 45509 | C5: =C14 -> 45510 | E5: =E14 -> 45511 | G5: =G14 -> 45512 | I5: =I14 -> 45513 | K5: =K14 -> 45514 | M5: =M14 -> 45515
A6: =IF(WEEKDAY($A$1,1)=startday,$A$1,"") | C6: =IF(A6="",IF(WEEKDAY($A$1,1)=MOD(startday,7)+1,$A$1,""),A6+1) | E6: =IF(C6="",IF(WEEKDAY($A$1,1)=MOD(startday,7)+2,$A$1,""),C6+1) | G6: =IF(E6="",IF(WEEKDAY($A$1,1)=MOD(startday,7)+3,$A$1,""),E6+1) -> 45505 | I6: =IF(G6="",IF(WEEKDAY($A$1,1)=MOD(startday,7)+4,$A$1,""),G6+1) -> 45506 | K6: =IF(I6="",IF(WEEKDAY($A$1,1)=MOD(startday,7)+5,$A$1,""),I6+1) -> 45507 | M6: =IF(K6="",IF(WEEKDAY($A$1,1)=MOD(startday+5,7)+1,$A$1,""),K6+1) -> 45508
M7: Haboubi
M8: Holiday
M9: Ander/Haboubi
M10: Liu
M11: Shafer
M12: Betsy (All New)
M13: Pham
A14: =M6+1 -> 45509 | C14: =A14+1 -> 45510 | E14: =C14+1 -> 45511 | G14: =E14+1 -> 45512 | I14: =G14+1 -> 45513 | K14: =I14+1 -> 45514 | M14: =K14+1 -> 45515
A15: Haboubi/Ander | C15: Haboubi | E15: Haboubi | G15: Haboubi | I15: Liu | K15: Liu | M15: Liu
A16: Holiday | C16: Holiday | E16: Holiday | G16: Holiday | I16: Robertson | K16: Robertson | M16: Robertson
A17: Ander | C17: Ander | E17: Ander | G17: Ander | I17: Remmel | K17: Remmel | M17: Remmel
A18: Liu | C18: Liu | E18: Liu | G18: Liu | I18: Liu | K18: Liu | M18: Liu
A19: Palade | C19: Palade | E19: Palade | G19: Palade | I19: Palade | K19: Palade | M19: Palade
A20: Kari (night) | C20: Kari (Night) | E20: Betsy/Marwa | G20: Betsy | I20: Kari (Night) | K20: Kari (All New) | M20: Kari (All New)
A21: Pham | C21: Pham | E21: Pham | G21: Pham (Night) | I21: Pham | K21: Pham | M21: Pham
A22: =M14+1 -> 45516 | C22: =A22+1 -> 45517 | E22: =C22+1 -> 45518 | G22: =E22+1 -> 45519 | I22: =G22+1 -> 45520 | K22: =I22+1 -> 45521 | M22: =K22+1 -> 45522
A23: Remmel | C23: Remmel | E23: Remmel | G23: Remmel | I23: Liu | K23: Liu | M23: Liu
A24: Robertson | C24: Robertson | E24: Robertson | G24: Robertson | I24: Hedera | K24: Hedera | M24: Hedera
A25: Brown | C25: Brown | E25: Brown | G25: Brown | I25: Brown | K25: Hernandez | M25: Hernandez
A26: Ding | C26: Ding | E26: Ding | G26: Ding | I26: Ding | K26: Ding | M26: Ding
A27: Shafer | C27: Shafer | E27: Shafer | G27: Shafer | I27: Shafer | K27: Shafer | M27: Shafer
A28: Kari | C28: Kari (night) | E28: Betsy (Night) | G28: Betsy | I28: Kari | K28: Kari | M28: Kari (All New)
A29: Haboubi (Haboubi) | C29: Haboubi | E29: Haboubi | G29: Haboubi (Night) | I29: Haboubi (Night) | K29: Haboubi (All New) | M29: Haboubi
A30: =M22+1 -> 45523 | C30: =A30+1 -> 45524 | E30: =C30+1 -> 45525 | G30: =E30+1 -> 45526 | I30: =G30+1 -> 45527 | K30: =I30+1 -> 45528 | M30: =K30+1 -> 45529
A31: Liu | C31: Liu | E31: Liu | G31: Liu | I31: Ander/Liu | K31: Ander | M31: Ander
A32: Hedera | C32: Hedera | E32: Hedera | G32: Hedera | I32: Shafer | K32: Shafer | M32: Shafer
A33: Ander | C33: Ander | E33: Ander | G33: Ander | I33: Sagi | K33: Elnazeir/Ander | M33: Elnazeir/Ander
A34: Liu | C34: Liu | E34: Abecassis | G34: Abecassis | I34: Abecassis | K34: Abecassis | M34: Abecassis
A35: Sagi | C35: Sagi | E35: Sagi | G35: Sagi | I35: Sagi | K35: Sagi | M35: Sagi
A36: Kari (Night) | C36: Betsy | E36: Betsy /Marwa | G36: Betsy | I36: Betsy (Night) | K36: Betsy (All New) | M36: Betsy (All New)
A37: Haboubi | C37: Haboubi (Night) | E37: Haboubi | G37: Haboubi (Night) | I37: Haboubi | K37: Haboubi | M37: Haboubi
A38: =IF(M30="","",IF(MONTH(M30+1)<>MONTH($A$1),"",M30+1)) -> 45530 | C38: =IF(A38="","",IF(MONTH(A38+1)<>MONTH($A$1),"",A38+1)) -> 45531 | E38: =IF(C38="","",IF(MONTH(C38+1)<>MONTH($A$1),"",C38+1)) -> 45532 | G38: =IF(E38="","",IF(MONTH(E38+1)<>MONTH($A$1),"",E38+1)) -> 45533 | I38: =IF(G38="","",IF(MONTH(G38+1)<>MONTH($A$1),"",G38+1)) -> 45534 | K38: =IF(I38="","",IF(MONTH(I38+1)<>MONTH($A$1),"",I38+1)) -> 45535 | M38: =IF(K38="","",IF(MONTH(K38+1)<>MONTH($A$1),"",K38+1))
A39: Ander | C39: Ander | E39: Ander | G39: Ander | I39: Haboubi/Ander | K39: Haboubi | M39: Haboubi
A40: Shafer | C40: Shafer | E40: Shafer | G40: Shafer | I40: Palade | K40: Palade | M40: Palade
...

Sheet Sept2021
A1: =EDATE('©'!A17,14) -> 45536
A2: Neurology Call Schedule
A3: ULH Stroke | C3: ULH General | E3: Jewish | G3: IR | I3: EMU | K3: Jasper/TRH/JS | M3: Good Sam
A4: =UPPER(TEXT(A1,"mmmm yyyy")) -> SEPTEMBER 2024
A5: =A14 -> 45537 | C5: =C14 -> 45538 | E5: =E14 -> 45539 | G5: =G14 -> 45540 | I5: =I14 -> 45541 | K5: =K14 -> 45542 | M5: =M14 -> 45543
A6: =IF(WEEKDAY($A$1,1)=startday,$A$1,"") | C6: =IF(A6="",IF(WEEKDAY($A$1,1)=MOD(startday,7)+1,$A$1,""),A6+1) | E6: =IF(C6="",IF(WEEKDAY($A$1,1)=MOD(startday,7)+2,$A$1,""),C6+1) | G6: =IF(E6="",IF(WEEKDAY($A$1,1)=MOD(startday,7)+3,$A$1,""),E6+1) | I6: =IF(G6="",IF(WEEKDAY($A$1,1)=MOD(startday,7)+4,$A$1,""),G6+1) | K6: =IF(I6="",IF(WEEKDAY($A$1,1)=MOD(startday,7)+5,$A$1,""),I6+1) | M6: =IF(K6="",IF(WEEKDAY($A$1,1)=MOD(startday+5,7)+1,$A$1,""),K6+1) -> 45536
E7: Haboubi | G7: Haboubi | I7: Liu/Remmel | K7: Liu/Remmel | M7: Liu/Remmel
E8: Palade | G8: Palade | I8: Wang | K8: Wang | M8: Wang
E9: Ander | G9: Ander | I9: Sagi | K9: Remmel | M9: Remmel
E10: Liu | G10: Liu | I10: Liu | K10: Liu | M10: Liu
E11: Shafer | G11: Shafer | I11: Shafer | K11: Shafer | M11: Shafer
E12: Kari | G12: Kari | I12: Kari (Night) | K12: Kari (All New) | M12: Kari (All New)
E13: Pham | G13: Pham (Night) | I13: Pham | K13: Pham | M13: Pham
A14: =M6+1 -> 45537 | C14: =A14+1 -> 45538 | E14: =C14+1 -> 45539 | G14: =E14+1 -> 45540 | I14: =G14+1 -> 45541 | K14: =I14+1 -> 45542 | M14: =K14+1 -> 45543
A15: Liu/Remmel | C15: Liu | E15: Liu/Remmel | G15: Liu | I15: Liu | K15: Liu | M15: Liu
A16: Wang | C16: Wang | E16: Wang | G16: Wang | I16: Brown | K16: Brown | M16: Brown
A17: Sagi/Remmel | C17: Sagi | E17: Sagi/Remmel | G17: Sagi | I17: Sagi | K17: Sagi | M17: Sagi
A18: Liu | C18: Abecassis | E18: Abecassis | G18: Abecassis | I18: Ding | K18: Ding | M18: Ding
A19: Palade | C19: Palade | E19: Palade | G19: Palade | I19: Palade | K19: Palade | M19: Palade
A20: Betsy (Night) | C20: Betsy /Kari night | E20: Betsy (night) | G20: Betsy | I20: Betsy (Night) | K20: Betsy (All new) | M20: Betsy (All New)
A21: Haboubi | C21: Haboubi | E21: Haboubi | G21: Haboubi (Night) | I21: Haboubi | K21: Haboubi | M21: Haboubi
A22: =M14+1 -> 45544 | C22: =A22+1 -> 45545 | E22: =C22+1 -> 45546 | G22: =E22+1 -> 45547 | I22: =G22+1 -> 45548 | K22: =I22+1 -> 45549 | M22: =K22+1 -> 45550
A23: Liu | C23: Liu | E23: Liu | G23: Liu | I23: Ander/Remmel | K23: Ander | M23: Ander
A24: Brown | C24: Brown | E24: Brown | G24: Brown | I24: Holiday | K24: Holiday | M24: Holiday
A25: Ander | C25: Ander | E25: Ander | G25: Ander | I25: Remmel | K25: Remmel/Ander | M25: Remmel/Ander
A26: Liu | C26: Liu | E26: Liu | G26: Ding | I26: Abecassis | K26: Abecassis | M26: Abecassis
A27: Sagi | C27: Sagi | E27: Sagi | G27: Sagi | I27: Sagi | K27: Sagi | M27: Sagi
A28: Kari (Night) | C28: Kari | E28: Betsy (Night) | G28: Kari | I28: Kari (night) | K28: Kari | M28: Kari
A29: Haboubi | C29: Haboubi (night) | E29: Haboubi | G29: Haboubi (night) | I29: Haboubi | K29: Haboubi (All New) | M29: Haboubi (All New)
A30: =M22+1 -> 45551 | C30: =A30+1 -> 45552 | E30: =C30+1 -> 45553 | G30: =E30+1 -> 45554 | I30: =G30+1 -> 45555 | K30: =I30+1 -> 45556 | M30: =K30+1 -> 45557
A31: Ander/Remmel | C31: Ander | E31: Ander | G31: Ander | I31: Haboubi/Haboubi | K31: Haboubi | M31: Haboubi/Ander
A32: Holiday | C32: Holiday | E32: Holiday | G32: Holiday | I32: Hedera | K32: Hedera | M32: Hedera
A33: Brown | C33: Brown | E33: Brown | G33: Brown | I33: Hernandez | K33: Hernandez/Haboubi | M33: Hernandez/Haboubi
A34: Ding | C34: Ding | E34: Liu | G34: Ding | I34: Ding | K34: Ding | M34: Ding
A35: Shafer | C35: Shafer | E35: Shafer | G35: Shafer | I35: Shafer | K35: Shafer | M35: Shafer
A36: Kari (Night) | C36: Kari (Night) | E36: Betsy | G36: Betsy | I36: Betsy | K36: Betsy | M36: Betsy
A37: Pham | C37: Pham | E37: Pham (Night) | G37: Pham (Night) | I37: Pham (Night) | K37: Pham (All New) | M37: Pham (All New)
A38: =IF(M30="","",IF(MONTH(M30+1)<>MONTH($A$1),"",M30+1)) -> 45558 | C38: =IF(A38="","",IF(MONTH(A38+1)<>MONTH($A$1),"",A38+1)) -> 45559 | E38: =IF(C38="","",IF(MONTH(C38+1)<>MONTH($A$1),"",C38+1)) -> 45560 | G38: =IF(E38="","",IF(MONTH(E38+1)<>MONTH($A$1),"",E38+1)) -> 45561 | I38: =IF(G38="","",IF(MONTH(G38+1)<>MONTH($A$1),"",G38+1)) -> 45562 | K38: =IF(I38="","",IF(MONTH(I38+1)<>MONTH($A$1),"",I38+1)) -> 45563 | M38: =IF(K38="","",IF(MONTH(K38+1)<>MONTH($A$1),"",K38+1)) -> 45564
A39: Haboubi/Ander | C39: Haboubi | E39: Haboubi | G39: Haboubi
A40: Hedera | C40: Hedera | E40: Hedera | G40: Hedera
...

Sheet Oct2021
A1: =EDATE('©'!A17,15) -> 45566
A2: Neurology Call Schedule
A3: ULH Stroke | C3: ULH General | E3: Jewish | G3: IR | I3: EMU | K3: Jasper/TRH/JS | M3: Good Sam
A4: =UPPER(TEXT(A1,"mmmm yyyy")) -> OCTOBER 2024
A5: =A14 -> 45572 | C5: =C14 -> 45573 | E5: =E14 -> 45574 | G5: =G14 -> 45575 | I5: =I14 -> 45576 | K5: =K14 -> 45577 | M5: =M14 -> 45578
A6: =IF(WEEKDAY($A$1,1)=startday,$A$1,"") | C6: =IF(A6="",IF(WEEKDAY($A$1,1)=MOD(startday,7)+1,$A$1,""),A6+1) -> 45566 | E6: =IF(C6="",IF(WEEKDAY($A$1,1)=MOD(startday,7)+2,$A$1,""),C6+1) -> 45567 | G6: =IF(E6="",IF(WEEKDAY($A$1,1)=MOD(startday,7)+3,$A$1,""),E6+1) -> 45568 | I6: =IF(G6="",IF(WEEKDAY($A$1,1)=MOD(startday,7)+4,$A$1,""),G6+1) -> 45569 | K6: =IF(I6="",IF(WEEKDAY($A$1,1)=MOD(startday,7)+5,$A$1,""),I6+1) -> 45570 | M6: =IF(K6="",IF(WEEKDAY($A$1,1)=MOD(startday+5,7)+1,$A$1,""),K6+1) -> 45571
I7: Liu/Remmel | K7: Liu/Remmel | M7: Liu/Remmel
I8: Robertson | K8: Robertson | M8: Robertson
I9: Ander | K9: Ander/Remmel | M9: Ander/Remmel
I10: Abecassis | K10: Abecassis | M10: Abecassis
I11: Evans | K11: Evans | M11: Evans
I12: Kari (Night) | K12: Kari (All New) | M12: Kari (All New)
I13: Haboubi | K13: Haboubi | M13: Haboubi
A14: =M6+1 -> 45572 | C14: =A14+1 -> 45573 | E14: =C14+1 -> 45574 | G14: =E14+1 -> 45575 | I14: =G14+1 -> 45576 | K14: =I14+1 -> 45577 | M14: =K14+1 -> 45578
A15: Liu/Remmel | C15: Liu/Remmel | E15: Liu/Ander | G15: Liu/Remmel | I15: Liu/Remmel | K15: Liu/Remmel | M15: Liu/Remmel
A16: Robertson | C16: Robertson | E16: Robertson | G16: Robertson | I16: Robertson | K16: Shafer | M16: Shafer
A17: Ander/Remmel | C17: Ander | E17: Ander | G17: Ander | I17: Ander/Remmel | K17: Sagi/Haboubi | M17: Sagi/Haboubi
A18: Abecassis | C18: Ding | E18: Ding | G18: Liu | I18: Liu | K18: Liu | M18: Liu
A19: Palade | C19: Palade | E19: Palade | G19: Palade | I19: Palade | K19: Palade | M19: Palade
A20: Kari (Night) | C20: Kari (Night) | E20: Kari | G20: Kari (Night) | I20: Kari (All New Day) | K20: Betsy | M20: Betsy
A21: Haboubi | C21: Haboubi | E21: Haboubi (Night) | G21: Haboubi | I21: Haboubi (Night) | K21: Haboubi (All New) | M21: Haboubi (All New)
A22: =M14+1 -> 45579 | C22: =A22+1 -> 45580 | E22: =C22+1 -> 45581 | G22: =E22+1 -> 45582 | I22: =G22+1 -> 45583 | K22: =I22+1 -> 45584 | M22: =K22+1 -> 45585
A23: Liu/Ander | C23: Liu | E23: Liu | G23: Liu | I23: Ander/Haboubi | K23: Ander | M23: Ander
A24: Shafer | C24: Shafer | E24: Shafer | G24: Shafer | I24: Holiday | K24: Holiday | M24: Holiday
A25: Brown | C25: Brown | E25: Brown | G25: Brown | I25: Hernandez | K25: Hernandez/Ander | M25: Hernandez/Ander
A26: Liu | C26: Abecassis | E26: Abecassis | G26: Abecassis | I26: Abecassis | K26: Abecassis | M26: Abecassis
A27: Sagi | C27: Sagi | E27: Sagi | G27: Sagi | I27: Sagi | K27: Sagi | M27: Sagi
A28: Betsy (Night) | C28: Betsy | E28: Betsy (Night) | G28: Betsy | I28: Betsy | K28: Kari | M28: Kari
A29: Haboubi | C29: Haboubi (Night) | E29: Haboubi | G29: Haboubi (Night) | I29: Haboubi/Elnazeir (Night) | K29: Elnazeir (All New) | M29: Elnazeir (All New)
A30: =M22+1 -> 45586 | C30: =A30+1 -> 45587 | E30: =C30+1 -> 45588 | G30: =E30+1 -> 45589 | I30: =G30+1 -> 45590 | K30: =I30+1 -> 45591 | M30: =K30+1 -> 45592
A31: Ander/Haboubi | C31: Ander | E31: Ander | G31: Ander | I31: Haboubi | K31: Haboubi | M31: Haboubi
A32: Holiday | C32: Holiday | E32: Holiday | G32: Holiday | I32: Wang | K32: Wang | M32: Wang
A33: Sagi | C33: Sagi | E33: Sagi | G33: Sagi | I33: Sagi | K33: Elnazeir | M33: Sagi
A34: Liu | C34: Liu | E34: Liu | G34: Ding | I34: Ding | K34: Ding | M34: Ding
A35: Shafer | C35: Shafer | E35: Shafer | G35: Shafer | I35: Shafer | K35: Shafer | M35: Shafer
A36: Betsy (Night) | C36: Kari (Night) | E36: Betsy (Night) | G36: Kari (Night) | I36: Kari | K36: Betsy (All New) | M36: Betsy (All New)
A37: Pham | C37: Pham | E37: Pham | G37: Pham | I37: Pham (Night) | K37: Pham | M37: Pham
A38: =IF(M30="","",IF(MONTH(M30+1)<>MONTH($A$1),"",M30+1)) -> 45593 | C38: 26 | E38: 27 | G38: 28 | I38: 29 | K38: 30 | M38: 31
A39: Haboubi/Ander | C39: Haboubi | E39: Haboubi/Ander | G39: Haboubi | I39: Liu | K39: Liu | M39: Liu
A40: Wang | C40: Wang | E40: Wang | G40: Wang | I40: Brown | K40: Brown | M40: Brown
...

Sheet Nov2021
A1: =EDATE('©'!A17,16) -> 45597
A3: ULH Stroke | C3: ULH General | E3: Jewish | G3: IR | I3: EMU | K3: Jasper/TRH/JS | M3: Good Sam
A4: =UPPER(TEXT(A1,"mmmm yyyy")) -> NOVEMBER 2024
A5: =A14 -> 45600 | C5: =C14 -> 45601 | E5: =E14 -> 45602 | G5: =G14 -> 45603 | I5: =I14 -> 45604 | K5: =K14 -> 45605 | M5: =M14 -> 45606
A6: =IF(WEEKDAY($A$1,1)=startday,$A$1,"") | C6: =IF(A6="",IF(WEEKDAY($A$1,1)=MOD(startday,7)+1,$A$1,""),A6+1) | E6: =IF(C6="",IF(WEEKDAY($A$1,1)=MOD(startday,7)+2,$A$1,""),C6+1) | G6: =IF(E6="",IF(WEEKDAY($A$1,1)=MOD(startday,7)+3,$A$1,""),E6+1) | I6: =IF(G6="",IF(WEEKDAY($A$1,1)=MOD(startday,7)+4,$A$1,""),G6+1) -> 45597 | K6: =IF(I6="",IF(WEEKDAY($A$1,1)=MOD(startday,7)+5,$A$1,""),I6+1) -> 45598 | M6: =IF(K6="",IF(WEEKDAY($A$1,1)=MOD(startday+5,7)+1,$A$1,""),K6+1) -> 45599
A7: Liu | C7: Liu | E7: Liu | G7: Ander | I7: Ander | K7: Ander/Remmel | M7: Ander
A8: Brown | C8: Brown | E8: Brown | G8: Brown | I8: Robertson | K8: Shafer | M8: Shafer
A9: Sagi | C9: Sagi | E9: Sagi | G9: Sagi | I9: Sagi | K9: Sagi | M9: Sagi
A10: Ding | C10: Ding | E10: Ding | G10: Ding | I10: Ding | K10: Ding | M10: Ding
A11: Shafer | C11: Shafer | E11: Shafer | G11: Shafer | I11: Shafer | K11: Shafer | M11: Shafer
A12: Kari | C12: Kari | E12: Betsy/Marwa (night) | G12: Kari | I12: Betsy/Marwa (Night) | K12: Betsy (All New) | M12: Betsy (All New)
A13: Haboubi (Night) | C13: Haboubi (Night) | E13: Haboubi | G13: Haboubi (Night) | I13: Haboubi | K13: Pham | M13: Pham
A14: =M6+1 -> 45600 | C14: =A14+1 -> 45601 | E14: =C14+1 -> 45602 | G14: =E14+1 -> 45603 | I14: =G14+1 -> 45604 | K14: =I14+1 -> 45605 | M14: =K14+1 -> 45606
A15: Ander/Haboubi | C15: Ander | E15: Ander/Remmel | G15: Ander | I15: Haboubi/Elnazeir | K15: Haboubi | M15: Haboubi
A16: Robertson | C16: Robertson | E16: Robertson | G16: Robertson | I16: Hedera | K16: Hedera | M16: Hedera
A17: Brown | C17: Brown | E17: Brown | G17: Brown | I17: Brown | K17: Hernandez | M17: Hernandez
A18: Ding | C18: Abecassis | E18: Abecassis | G18: Abecassis | I18: Abecassis | K18: Abecassis | M18: Abecassis
A19: Palade | C19: Palade | E19: Palade | G19: Palade | I19: Palade | K19: Palade | M19: Palade
A20: Betsy (Night) | C20: Betsy/Kari (night) | E20: Betsy/Jones (Night) | G20: Betsy/Jones (Night) | I20: Kari (Night) | K20: Kari | M20: Kari
A21: Pham | C21: Pham | E21: Pham | G21: Pham | I21: Pham | K21: Pham (All New) | M21: Pham (All New)
A22: =M14+1 -> 45607 | C22: =A22+1 -> 45608 | E22: =C22+1 -> 45609 | G22: =E22+1 -> 45610 | I22: =G22+1 -> 45611 | K22: =I22+1 -> 45612 | M22: =K22+1 -> 45613
A23: Haboubi/Ander | C23: Haboubi | E23: Haboubi/Ander | G23: Haboubi | I23: Liu/Ander | K23: Liu/Ander | M23: Liu/Ander
A24: Hedera | C24: Hedera | E24: Hedera | G24: Hedera | I24: Palade | K24: Palade | M24: Palade
A25: Sagi | C25: Remmel | E25: Remmel | G25: Remmel | I25: Remmel | K25: Remmel | M25: Remmel
A26: Abecassis | C26: Abecassis | E26: Abecassis | G26: Abecassis | I26: Liu | K26: Liu | M26: Liu
A27: Sagi | C27: Sagi | E27: Sagi | G27: Sagi | I27: Sagi | K27: Sagi | M27: Sagi
A28: Nancy Ashley | C28: Nancy Ashley | E28: Nancy Ashley | G28: Nancy Ashley | I28: Nancy Ashley | K28: Nancy Ashley | M28: Nancy Ashley
A29: Pham (Night) | C29: Pham (Night) | E29: Pham (Night) | G29: Pham (Night) | I29: Pham/Haboubi (Night) | K29: Haboubi (All New) | M29: Haboubi (All New)
A30: =M22+1 -> 45614 | C30: =A30+1 -> 45615 | E30: =C30+1 -> 45616 | G30: =E30+1 -> 45617 | I30: =G30+1 -> 45618 | K30: =I30+1 -> 45619 | M30: =K30+1 -> 45620
A31: Liu/Remmel | C31: Liu/Remmel | E31: Liu/Remmel | G31: Liu/Remmel | I31: Liu/Remmel | K31: Liu/Remmel | M31: Liu/Remmel
A32: Palade | C32: Palade | E32: Palade | G32: Palade | I32: Robertson | K32: Robertson | M32: Robertson
A33: Ander | C33: Ander | E33: Ander | G33: Ander | I33: Ander | K33: Ander/Remmel | M33: Ander/Remmel
A34: Liu | C34: Liu | E34: Liu | G34: Liu | I34: Liu | K34: Liu | M34: Liu
A35: Shafer | C35: Shafer | E35: Shafer | G35: Shafer | I35: Palade | K35: Palade | M35: Shafer
A36: Betsy (Night) | C36: Betsy | E36: Betsy (Night) | G36: Kari (All New) | I36: Kari (Night) | K36: Kari | M36: Kari (All New)
A37: Haboubi | C37: Haboubi (Night) | E37: Haboubi | G37: Haboubi | I37: Haboubi | K37: Jones (All New) | M37: Haboubi
A38: =IF(M30="","",IF(MONTH(M30+1)<>MONTH($A$1),"",M30+1)) -> 45621 | C38: =IF(A38="","",IF(MONTH(A38+1)<>MONTH($A$1),"",A38+1)) -> 45622 | E38: =IF(C38="","",IF(MONTH(C38+1)<>MONTH($A$1),"",C38+1)) -> 45623 | G38: =IF(E38="","",IF(MONTH(E38+1)<>MONTH($A$1),"",E38+1)) -> 45624 | I38: =IF(G38="","",IF(MONTH(G38+1)<>MONTH($A$1),"",G38+1)) -> 45625 | K38: =IF(I38="","",IF(MONTH(I38+1)<>MONTH($A$1),"",I38+1)) -> 45626 | M38: =IF(K38="","",IF(MONTH(K38+1)<>MONTH($A$1),"",K38+1))
A39: Liu/Elnazeir | C39: Liu
A40: Shafer | C40: Shafer
A41: Sagi | C41: Sagi
...

Sheet Dec2021
A1: =EDATE('©'!A17,17) -> 45627
A2: Neurology Call Schedule
A3: ULH Stroke | C3: ULH General | E3: Jewish | G3: IR | I3: EMU | K3: Jasper/TRH/JS | M3: Good Sam
A4: =UPPER(TEXT(A1,"mmmm yyyy")) -> DECEMBER 2024
A5: =A14 -> 45628 | C5: =C14 -> 45629 | E5: =E14 -> 45630 | G5: =G14 -> 45631 | I5: =I14 -> 45632 | K5: =K14 -> 45633 | M5: =M14 -> 45634
A6: =IF(WEEKDAY($A$1,1)=startday,$A$1,"") | C6: =IF(A6="",IF(WEEKDAY($A$1,1)=MOD(startday,7)+1,$A$1,""),A6+1) | E6: =IF(C6="",IF(WEEKDAY($A$1,1)=MOD(startday,7)+2,$A$1,""),C6+1) | G6: =IF(E6="",IF(WEEKDAY($A$1,1)=MOD(startday,7)+3,$A$1,""),E6+1) | I6: =IF(G6="",IF(WEEKDAY($A$1,1)=MOD(startday,7)+4,$A$1,""),G6+1) | K6: =IF(I6="",IF(WEEKDAY($A$1,1)=MOD(startday,7)+5,$A$1,""),I6+1) | M6: =IF(K6="",IF(WEEKDAY($A$1,1)=MOD(startday+5,7)+1,$A$1,""),K6+1) -> 45627
E7: Liu/Haboubi | G7: Liu/Haboubi? | I7: Haboubi/Remmel | K7: Haboubi | M7: Haboubi
E8: Shafer | G8: Shafer | I8: Shafer | K8: Shafer | M8: Shafer
E9: Ander | G9: Ander | I9: Ander/Remmel | K9: Remmel | M9: Remmel
E10: Ding | G10: Ding | I10: Abecassis | K10: Abecassis | M10: Abecassis
E11: Palade | G11: Palade | I11: Palade | K11: Palade | M11: Palade
E12: Betsy (Night) | G12: Kari | I12: Kari (All) | K12: Kari (All) | M12: Kari (All)
E13: Pham | G13: Pham (Night) | I13: Pham | K13: Pham | M13: Pham
A14: =M6+1 -> 45628 | C14: =A14+1 -> 45629 | E14: =C14+1 -> 45630 | G14: =E14+1 -> 45631 | I14: =G14+1 -> 45632 | K14: =I14+1 -> 45633 | M14: =K14+1 -> 45634
A15: Haboubi/Ander | C15: Haboubi | E15: Haboubi/Ander | G15: Haboubi | I15: Ander/Haboubi | K15: Ander | M15: Ander
A16: Robertson | C16: Robertson | E16: Robertson | G16: Robertson | I16: Brown | K16: Brown | M16: Brown
A17: Ander | C17: Ander | E17: Ander | G17: Ander | I17: Sagi | K17: Elnazeir | M17: Elnazeir
A18: Abecassis | C18: Abecassis | E18: Abecassis | G18: Abecassis | I18: Liu | K18: Liu | M18: Liu
A19: Shafer | C19: Shafer | E19: Shafer | G19: Shafer | I19: Shafer | K19: Shafer | M19: Shafer
A20: Kari | C20: Kari | E20: Betsy (Night) | G20: Betsy | I20: Betsy (All) | K20: Betsy (All) | M20: Betsy (All)
A21: Jones (Night) | C21: Jones (Night) | E21: Jones | G21: Jones (Night) | I21: Jones | K21: Jones | M21: Jones
A22: =M14+1 -> 45635 | C22: =A22+1 -> 45636 | E22: =C22+1 -> 45637 | G22: =E22+1 -> 45638 | I22: =G22+1 -> 45639 | K22: =I22+1 -> 45640 | M22: =K22+1 -> 45641
A23: Ander/Haboubi | C23: Ander | E23: Liu/Remmel | G23: Liu/Remmel | I23: Liu/Remmel | K23: Liu/Remmel | M23: Liu/Remmel
A24: Brown | C24: Brown | E24: Brown | G24: Brown | I24: Wang | K24: Wang | M24: Wang
A25: Sagi | C25: Sagi | E25: Sagi | G25: Sagi | I25: Holiday | K25: Marwa | M25: Marwa
A26: Liu | C26: Liu | E26: Liu | G26: Liu | I26: Liu | K26: Liu | M26: Liu
A27: Evans | C27: Evans | E27: Evans | G27: Evans | I27: Evans | K27: Evans | M27: Evans
A28: Betsy | C28: Betsy | E28: Betsy | G28: Kari | I28: Kari | K28: Kari | M28: Kari
A29: Haboubi/Jones (night) | C29: Haboubi/Jones (night) | E29: Haboubi (Night) | G29: Haboubi (Night) | I29: Haboubi/Jones (night) | K29: Jones (All New) | M29: Jones (All New)/Haboubi night
A30: =M22+1 -> 45642 | C30: =A30+1 -> 45643 | E30: =C30+1 -> 45644 | G30: =E30+1 -> 45645 | I30: =G30+1 -> 45646 | K30: =I30+1 -> 45647 | M30: =K30+1 -> 45648
A31: Liu/Ander | C31: Liu | E31: Ander/Elnazeir | G31: Ander | I31: Ander | K31: Ander | M31: Haboubi
A32: Wang | C32: Wang | E32: Wang | G32: Wang | I32: Holiday | K32: Holiday | M32: Holiday
A33: Remmel | C33: Remmel | E33: Sagi | G33: Sagi | I33: Sagi | K33: Sagi | M33: Sagi
A34: Liu | C34: Ding | E34: Ding | G34: Ding | I34: Ding | K34: Ding | M34: Ding
A35: Palade | C35: Palade | E35: Palade | G35: Palade | I35: Palade | K35: Palade | M35: Palade
A36: Kari (Night) | C36: Kari (Night) | E36: Kari | G36: Kari | I36: Betsy | K36: Betsy | M36: Betsy
A37: Pham | C37: Pham | E37: Pham (Night) | G37: Pham (Night) | I37: Pham (Night) | K37: Pham (All) | M37: Pham (All)
A38: =IF(M30="","",IF(MONTH(M30+1)<>MONTH($A$1),"",M30+1)) -> 45649 | C38: =IF(A38="","",IF(MONTH(A38+1)<>MONTH($A$1),"",A38+1)) -> 45650 | E38: =IF(C38="","",IF(MONTH(C38+1)<>MONTH($A$1),"",C38+1)) -> 45651 | G38: =IF(E38="","",IF(MONTH(E38+1)<>MONTH($A$1),"",E38+1)) -> 45652 | I38: =IF(G38="","",IF(MONTH(G38+1)<>MONTH($A$1),"",G38+1)) -> 45653 | K38: =IF(I38="","",IF(MONTH(I38+1)<>MONTH($A$1),"",I38+1)) -> 45654 | M38: =IF(K38="","",IF(MONTH(K38+1)<>MONTH($A$1),"",K38+1)) -> 45655
A39: Haboubi | C39: Haboubi | E39: Haboubi/Elnazeir | G39: Haboubi | I39: Haboubi/Remmel
A40: Holiday | C40: Holiday | E40: Holiday | G40: Holiday | I40: Hedera
...

Sheet Jan2022
A1: =EDATE('©'!A17,18) -> 45658 | K1: (c) 2011 Vertex42 LLC
A2: Neurology Call Schedule
A3: ULH Stroke | C3: ULH General | E3: Jewish | G3: IR | I3: EMU | K3: Jasper/TRH/JS | M3: Good Sam
A4: =UPPER(TEXT(A1,"mmmm yyyy")) -> JANUARY 2025
A5: =A14 -> 45663 | C5: =C14 -> 45664 | E5: =E14 -> 45665 | G5: =G14 -> 45666 | I5: =I14 -> 45667 | K5: =K14 -> 45668 | M5: =M14 -> 45669
A6: =IF(WEEKDAY($A$1,1)=startday,$A$1,"") | C6: =IF(A6="",IF(WEEKDAY($A$1,1)=MOD(startday,7)+1,$A$1,""),A6+1) | E6: =IF(C6="",IF(WEEKDAY($A$1,1)=MOD(startday,7)+2,$A$1,""),C6+1) -> 45658 | G6: =IF(E6="",IF(WEEKDAY($A$1,1)=MOD(startday,7)+3,$A$1,""),E6+1) -> 45659 | I6: =IF(G6="",IF(WEEKDAY($A$1,1)=MOD(startday,7)+4,$A$1,""),G6+1) -> 45660 | K6: =IF(I6="",IF(WEEKDAY($A$1,1)=MOD(startday,7)+5,$A$1,""),I6+1) -> 45661 | M6: =IF(K6="",IF(WEEKDAY($A$1,1)=MOD(startday+5,7)+1,$A$1,""),K6+1) -> 45662
K7: Remmel/Marwa | M7: Remmel/Marwa
K8: Hedera | M8: Hedera
K9: Elnazeir | M9: Elnazeir
K10: Abecassis | M10: Abecassis
K11: Shafer | M11: Shafer
K12: Kari | M12: Kari
K13: Jones (All new) | M13: Haboubi (All new)
A14: =M6+1 -> 45663 | C14: =A14+1 -> 45664 | E14: =C14+1 -> 45665 | G14: =E14+1 -> 45666 | I14: =G14+1 -> 45667 | K14: =I14+1 -> 45668 | M14: =K14+1 -> 45669
A15: Liu/Haboubi | C15: Liu/Remmel | E15: Liu/Haboubi | G15: Ander | I15: Ander/Liu | K15: Ander | M15: Ander
A16: Hedera | C16: Hedera | E16: Hedera | G16: Hedera | I16: Robertson | K16: Robertson | M16: Robertson
A17: Brown | C17: Brown | E17: Brown | G17: Brown | I17: Brown | K17: Remmel | M17: Remmel
A18: Liu | C18: Liu | E18: Liu | G18: Liu | I18: Liu | K18: Liu | M18: Liu
A19: Palade | C19: Palade | E19: Palade | G19: Palade | I19: Palade | K19: Palade | M19: Palade
A20: Kari (Night) | C20: Kari (Night) | E20: Betsy (Night) | G20: Kari | I20: Kari (Night) | K20: Kari (All new) | M20: Kari (All new)
A21: Haboubi | C21: Nancy Ashley | E21: Nancy Ashley | G21: Haboubi (all new) | I21: Haboubi | K21: Haboubi | M21: Haboubi
A22: =M14+1 -> 45670 | C22: =A22+1 -> 45671 | E22: =C22+1 -> 45672 | G22: =E22+1 -> 45673 | I22: =G22+1 -> 45674 | K22: =I22+1 -> 45675 | M22: =K22+1 -> 45676
A23: Ander/Haboubi | C23: Ander | E23: Ander/Haboubi | G23: Ander | I23: Haboubi | K23: Haboubi | M23: Haboubi/Ander
A24: Robertson | C24: Robertson | E24: Robertson | G24: Robertson | I24: Shafer | K24: Shafer | M24: Shafer
A25: Remmel | C25: Remmel | E25: Remmel | G25: Remmel | I25: Remmel | K25: Hernandez | M25: Hernandez
A26: Ding | C26: Ding | E26: Ding | G26: Ding | I26: Ding | K26: Ding | M26: Ding
A27: Evans | C27: Evans | E27: Evans | G27: Evans | I27: Evans | K27: Evans | M27: Evans
A28: Betsy | C28: Betsy | E28: Betsy (Night) | G28: Betsy | I28: Betsy | K28: Betsy | M28: Betsy
A29: Pham(Night) | C29: Pham (Night) | E29: Pham | G29: Pham (Night) | I29: Pham (all new) | K29: Pham (all new) | M29: Pham (all new)
A30: =M22+1 -> 45677 | C30: =A30+1 -> 45678 | E30: =C30+1 -> 45679 | G30: =E30+1 -> 45680 | I30: =G30+1 -> 45681 | K30: =I30+1 -> 45682 | M30: =K30+1 -> 45683
A31: Haboubi/Marwa | C31: Haboubi | E31: Haboubi/Marwa | G31: Haboubi | I31: Liu/Ander | K31: Liu | M31: Liu
A32: Shafer | C32: Shafer | E32: Shafer | G32: Shafer | I32: Wang | K32: Wang | M32: Wang
A33: Ander/Marwa | C33: Ander | E33: Ander | G33: Ander | I33: Ander | K33: Ander | M33: Ander
A34: Liu | C34: Ding | E34: Ding | G34: Abecassis | I34: Abecassis | K34: Abecassis | M34: Abecassis
A35: Palade | C35: Palade | E35: Palade | G35: Palade | I35: Shafer | K35: Shafer | M35: Shafer
A36: Kari (Night) | C36: Kari (Night) | E36: Betsy (Night) | G36: Kari | I36: Kari | K36: Kari | M36: Kari
A37: Pham | C37: Pham | E37: Pham | G37: Pham (Night) | I37: Pham/Jones (all new-night) | K37: Jones (all new) | M37: Jones (all new)
A38: =IF(M30="","",IF(MONTH(M30+1)<>MONTH($A$1),"",M30+1)) -> 45684 | C38: =IF(A38="","",IF(MONTH(A38+1)<>MONTH($A$1),"",A38+1)) -> 45685 | E38: =IF(C38="","",IF(MONTH(C38+1)<>MONTH($A$1),"",C38+1)) -> 45686 | G38: =IF(E38="","",IF(MONTH(E38+1)<>MONTH($A$1),"",E38+1)) -> 45687 | I38: =IF(G38="","",IF(MONTH(G38+1)<>MONTH($A$1),"",G38+1)) -> 45688 | K38: =IF(I38="","",IF(MONTH(I38+1)<>MONTH($A$1),"",I38+1)) | M38: =IF(K38="","",IF(MONTH(K38+1)<>MONTH($A$1),"",K38+1))
A39: Liu | C39: Liu | E39: Liu | G39: Liu | I39: Liu | K39: Liu | M39: Liu
A40: Wang | C40: Wang | E40: Wang | G40: Wang | I40: Holiday | K40: Holiday | M40: Holiday
...

Sheet June 2026
A1: =EDATE('©'!A17,35) -> 46174 | K1: (c) 2011 Vertex42 LLC
A2: Child Neurology Call Schedule
A3: General | C3: ICU | E3: CEEG/LTM EEG Reader | G3: EMU 1/Surgery/1st 5 Admission at NCH | I3: EMU2/Remaining NCH EMU patients/NWC EMU Patients | K3: Out of Office Clinic | M3: P2P
A4: =UPPER(TEXT(A1,"mmmm yyyy")) -> JUNE 2026
A5: =A15 -> 46181 | C5: =C15 -> 46182 | E5: =E15 -> 46183 | G5: =G15 -> 46184 | I5: =I15 -> 46185 | K5: =K15 -> 46186 | M5: =M15 -> 46187
A6: =IF(WEEKDAY($A$1,1)=startday,$A$1,"") -> 46174 | C6: =IF(A6="",IF(WEEKDAY($A$1,1)=MOD(startday,7)+1,$A$1,""),A6+1) -> 46175 | E6: =IF(C6="",IF(WEEKDAY($A$1,1)=MOD(startday,7)+2,$A$1,""),C6+1) -> 46176 | G6: =IF(E6="",IF(WEEKDAY($A$1,1)=MOD(startday,7)+3,$A$1,""),E6+1) -> 46177 | I6: =IF(G6="",IF(WEEKDAY($A$1,1)=MOD(startday,7)+4,$A$1,""),G6+1) -> 46178 | K6: =IF(I6="",IF(WEEKDAY($A$1,1)=MOD(startday,7)+5,$A$1,""),I6+1) -> 46179 | M6: =IF(K6="",IF(WEEKDAY($A$1,1)=MOD(startday+5,7)+1,$A$1,""),K6+1) -> 46180
A7: Lakhotia | C7: Lakhotia | E7: Lakhotia | G7: Lakhotia | I7: Lakhotia | K7: Lakhotia | M7: Lakhotia
A8: Marshall | C8: Marshall | E8: Marshall | G8: Marshall | I8: Marshall
A9: Shoup | C9: Shoup | E9: Shoup | G9: Shoup | I9: Shoup | K9: Shoup | M9: Shoup
A10: Karia | C10: Karia | E10: Karia | G10: Karia | I10: Karia
A13: Means | C13: Means | E13: Means | G13: Means | I13: Means | K13: Means | M13: Means
A14: Ravishankar | C14: Patel | E14: Raichur | G14: Danieli | I14: Lechtefeld | K14: Lechtefeld/Raichur | M14: Danieli
A15: =M6+1 -> 46181 | C15: =A15+1 -> 46182 | E15: =C15+1 -> 46183 | G15: =E15+1 -> 46184 | I15: =G15+1 -> 46185 | K15: =I15+1 -> 46186 | M15: =K15+1 -> 46187
A16: Hocker | C16: Hocker | E16: Hocker | G16: Hocker | I16: Hocker | K16: Hocker | M16: Hocker
A17: Doll | C17: Doll | E17: Doll | G17: Doll | I17: Doll
A18: Clements | C18: Clements | E18: Clements | G18: Clements | I18: Farber | K18: Farber | M18: Farber
A19: Sah | C19: Sah | E19: Sah | G19: Sah | I19: Sah
A22: Evans | C22: Evans | E22: Evans | G22: Evans | I22: Evans | K22: Evans | M22: Evans
A23: Benton | C23: Rozena | E23: Patel | G23: Lichtefeld | I23: Danieli | K23: Danieli/Hey | M23: Patel
A24: =M15+1 -> 46188 | C24: =A24+1 -> 46189 | E24: =C24+1 -> 46190 | G24: =E24+1 -> 46191 | I24: =G24+1 -> 46192 | K24: =I24+1 -> 46193 | M24: =K24+1 -> 46194
A25: Brock | C25: Brock | E25: Brock | G25: Brock | I25: Brock | K25: Means | M25: Means
A26: Means | C26: Means | E26: Means | G26: Means | I26: Means
A27: Barnes | C27: Barnes | E27: Barnes | G27: Barnes | I27: Barnes | K27: Barnes | M27: Barnes
A28: Shoup | C28: Shoup | E28: Shoup | G28: Shoup | I28: Shoup
A31: Rogers | C31: Rogers | E31: Rogers | G31: Rogers | I31: Rogers | K31: Rogers | M31: Rogers
A32: Lichtefeld | C32: Ravishankar | E32: Lechtefeld | G32: Danieli | I32: Ravishankar | K32: Ravishankar/Hey | M32: Patel
A33: =M24+1 -> 46195 | C33: =A33+1 -> 46196 | E33: =C33+1 -> 46197 | G33: =E33+1 -> 46198 | I33: =G33+1 -> 46199 | K33: =I33+1 -> 46200 | M33: =K33+1 -> 46201
A34: Brock | C34: Brock | E34: Brock | G34: Brock | I34: Brock | K34: Brock | M34: Brock
A35: Doll | C35: Doll | E35: Doll | G35: Doll | I35: Doll
A36: Farber | C36: Farber | E36: Farber | G36: Farber | I36: Clements | K36: Clements | M36: Clements
A37: Karia | C37: Karia | E37: Karia | G37: Karia | I37: Karia
A41: Rozena | C41: Lechtefeld | E41: Tison-Brandon | G41: Ravishankar | I41: Patel | K41: Patel | M41: Benton
A42: =IF(M33="","",IF(MONTH(M33+1)<>MONTH($A$1),"",M33+1)) -> 46202 | C42: =IF(A42="","",IF(MONTH(A42+1)<>MONTH($A$1),"",A42+1)) -> 46203 | E42: 1 | G42: 2 | I42: 3 | K42: 4 | M42: 5
A43: Barton | C43: Barton | E43: Barton | G43: Barton | I43: Barton | K43: Barton | M43: Barton
A44: Means | C44: Means | E44: Means | G44: Means | I44: Means
A45: Sah | C45: Sah | E45: Sah | G45: Sah | I45: Sah | K45: Sah | M45: Sah
A46: Karia | C46: Karia | E46: Karia | G46: Karia | I46: Karia
A50: Danieli | C50: Ravishankar
E51: Notes:
E58: © 2011-2019 by Vertex42.com. Free to print. | I58: =HYPERLINK("https://www.vertex42.com/calendars/academic-calendar.html","https://www.vertex42.com/calendars/academic-calendar.html") -> https://www.vertex42.com/calendars/academic-calendar.html

Sheet July 2026
A1: =EDATE('©'!A17,36) -> 46204 | K1: (c) 2011 Vertex42 LLC
A2: Child Neurology Call Schedule
A3: General | C3: ICU | E3: CEEG/LTM EEG Reader | G3: EMU 1/Surgery/1st 5 Admission at NCH | I3: EMU2/Remaining NCH EMU patients/NWC EMU Patients | K3: Out of Office Clinic | M3: P2P
A4: =UPPER(TEXT(A1,"mmmm yyyy")) -> JULY 2026
A5: =A15 -> 46209 | C5: =C15 -> 46210 | E5: =E15 -> 46211 | G5: =G15 -> 46212 | I5: =I15 -> 46213 | K5: =K15 -> 46214 | M5: =M15 -> 46215
A6: =IF(WEEKDAY($A$1,1)=startday,$A$1,"") | C6: =IF(A6="",IF(WEEKDAY($A$1,1)=MOD(startday,7)+1,$A$1,""),A6+1) | E6: =IF(C6="",IF(WEEKDAY($A$1,1)=MOD(startday,7)+2,$A$1,""),C6+1) -> 46204 | G6: =IF(E6="",IF(WEEKDAY($A$1,1)=MOD(startday,7)+3,$A$1,""),E6+1) -> 46205 | I6: =IF(G6="",IF(WEEKDAY($A$1,1)=MOD(startday,7)+4,$A$1,""),G6+1) -> 46206 | K6: =IF(I6="",IF(WEEKDAY($A$1,1)=MOD(startday,7)+5,$A$1,""),I6+1) -> 46207 | L6: 4th of July | M6: =IF(K6="",IF(WEEKDAY($A$1,1)=MOD(startday+5,7)+1,$A$1,""),K6+1) -> 46208
A7: Barton | C7: Barton | E7: Barton | G7: Barton | I7: Barton | K7: Barton | M7: Barton
A8: Means | C8: Means | E8: Means | G8: Means | I8: Means
A9: Sah | C9: Sah | E9: Sah | G9: Sah | I9: Sah | K9: Sah | M9: Sah
A10: Karia | C10: Karia | E10: Karia | G10: Karia | I10: Karia
A15: =M6+1 -> 46209 | C15: =A15+1 -> 46210 | E15: =C15+1 -> 46211 | G15: =E15+1 -> 46212 | I15: =G15+1 -> 46213 | K15: =I15+1 -> 46214 | M15: =K15+1 -> 46215
A16: Marshall | C16: Marshall | E16: Marshall | G16: Marshall | I16: Marshall | K16: Marshall | M16: Marshall
A17: Sweeney | C17: Sweeney | E17: Sweeney | G17: Sweeney | I17: Sweeney
A18: Jain | C18: Jain | E18: Jain | G18: Jain | I18: Jain | K18: Jain | M18: Jain
A19: Shoup | C19: Shoup | E19: Shoup | G19: Shoup | I19: Shoup
A24: =M15+1 -> 46216 | C24: =A24+1 -> 46217 | E24: =C24+1 -> 46218 | G24: =E24+1 -> 46219 | I24: =G24+1 -> 46220 | K24: =I24+1 -> 46221 | M24: =K24+1 -> 46222
A25: Puri | C25: Puri(Farber 5p-10p) | E25: Puri | G25: Puri | I25: Puri | K25: Puri | M25: Puri
A26: Means | C26: Means | E26: Means | G26: Means | I26: Means
A27: Farber | C27: Farber | E27: Farber | G27: Farber | I27: Farber | K27: Farber | M27: Farber
A28: Jain | C28: Jain | E28: Jain | G28: Jain | I28: Jain
A33: =M24+1 -> 46223 | C33: =A33+1 -> 46224 | E33: =C33+1 -> 46225 | G33: =E33+1 -> 46226 | I33: =G33+1 -> 46227 | K33: =I33+1 -> 46228 | M33: =K33+1 -> 46229
A34: Sweeney | C34: Sweeney | E34: Sweeney | G34: Sweeney | I34: Sweeney | K34: Sweeney | M34: Sweeney
A35: Singer | C35: Singer | E35: Singer | G35: Singer | I35: Singer
A36: Clements | C36: Clements | E36: Clements | G36: Clements | I36: Clements | K36: Clements | M36: Clements
A37: Sah | C37: Sah | E37: Sah | G37: Sah | I37: Sah
A42: =IF(M33="","",IF(MONTH(M33+1)<>MONTH($A$1),"",M33+1)) -> 46230 | C42: =IF(A42="","",IF(MONTH(A42+1)<>MONTH($A$1),"",A42+1)) -> 46231 | E42: =IF(C42="","",IF(MONTH(C42+1)<>MONTH($A$1),"",C42+1)) -> 46232 | G42: 30 | I42: 31
A43: Singer | C43: Singer | E43: Singer | G43: Singer | I43: Singer | K43: Singer | M43: Singer
A44: Sweeney | C44: Sweeney | E44: Sweeney | G44: Sweeney | I44: Sweeney
A45: Farber | C45: Farber | E45: Farber | G45: Farber | I45: Farber | K45: Farber | M45: Farber
A46: Marashly | C46: Marashly | E46: Marashly | G46: Marashly | I46: Marashly
E51: Notes:
